Workbook

Sheet Overview
A1: ANNUAL OVERVIEW — 2026 BUDGET DASHBOARD
A3: 📅 MONTHLY SUMMARY | J3: 📊 YEARLY DASHBOARD | U3: Chart data (auto — leave as is)
A4: Month | B4: Total Income | C4: Needs | D4: Wants | E4: Savings/Invest | F4: Total Expenses | G4: Surplus/Deficit | H4: Savings Rate | J4: YTD Income | L4: YTD Expenses | N4: YTD Savings | P4: YTD Surplus | R4: Avg Savings Rate | U4: Category | V4: Amount
A5: January | B5: =Jan!B12 -> 80000 | C5: =Jan!B24 -> 42000 | D5: =Jan!B35 -> 13000 | E5: =Jan!B46 -> 21000 | F5: =C5+D5 -> 55000 | G5: =B5-C5-D5-E5 -> 4000 | H5: =IF(B5=0,0,E5/B5) -> 0.2625 | J5: =B17 -> 80000 | L5: =F17 -> 55000 | N5: =E17 -> 21000 | P5: =G17 -> 4000 | R5: =H17 -> 0.2625 | U5: Needs | V5: =C17 -> 42000
A6: February | B6: =Feb!B12 -> 0 | C6: =Feb!B24 -> 0 | D6: =Feb!B35 -> 0 | E6: =Feb!B46 -> 0 | F6: =C6+D6 -> 0 | G6: =B6-C6-D6-E6 -> 0 | H6: =IF(B6=0,0,E6/B6) -> 0 | U6: Wants | V6: =D17 -> 13000
A7: March | B7: =Mar!B12 -> 0 | C7: =Mar!B24 -> 0 | D7: =Mar!B35 -> 0 | E7: =Mar!B46 -> 0 | F7: =C7+D7 -> 0 | G7: =B7-C7-D7-E7 -> 0 | H7: =IF(B7=0,0,E7/B7) -> 0 | J7: ✅ YEARLY HEALTH CHECK — 50 / 30 / 20 Rule | U7: Savings/Invest | V7: =E17 -> 21000
A8: April | B8: =Apr!B12 -> 0 | C8: =Apr!B24 -> 0 | D8: =Apr!B35 -> 0 | E8: =Apr!B46 -> 0 | F8: =C8+D8 -> 0 | G8: =B8-C8-D8-E8 -> 0 | H8: =IF(B8=0,0,E8/B8) -> 0 | J8: Category | K8: Actual Amount | L8: Actual % | M8: Target % | N8: Status | U8: Unallocated | V8: =MAX(B17-C17-D17-E17,0) -> 4000
A9: May | B9: =May!B12 -> 0 | C9: =May!B24 -> 0 | D9: =May!B35 -> 0 | E9: =May!B46 -> 0 | F9: =C9+D9 -> 0 | G9: =B9-C9-D9-E9 -> 0 | H9: =IF(B9=0,0,E9/B9) -> 0 | J9: Needs (Essentials) | K9: =C17 -> 42000 | L9: =IF($B$17=0,0,K9/$B$17) -> 0.525 | M9: 0.5 | N9: =IF(L9<=M9,"✅ On Track","⚠️ Over Budget") -> ⚠️ Over Budget
A10: June | B10: =Jun!B12 -> 0 | C10: =Jun!B24 -> 0 | D10: =Jun!B35 -> 0 | E10: =Jun!B46 -> 0 | F10: =C10+D10 -> 0 | G10: =B10-C10-D10-E10 -> 0 | H10: =IF(B10=0,0,E10/B10) -> 0 | J10: Wants (Lifestyle) | K10: =D17 -> 13000 | L10: =IF($B$17=0,0,K10/$B$17) -> 0.1625 | M10: 0.3 | N10: =IF(L10<=M10,"✅ On Track","⚠️ Over Budget") -> ✅ On Track
A11: July | B11: =Jul!B12 -> 0 | C11: =Jul!B24 -> 0 | D11: =Jul!B35 -> 0 | E11: =Jul!B46 -> 0 | F11: =C11+D11 -> 0 | G11: =B11-C11-D11-E11 -> 0 | H11: =IF(B11=0,0,E11/B11) -> 0 | J11: Savings & Investments | K11: =E17 -> 21000 | L11: =IF($B$17=0,0,K11/$B$17) -> 0.2625 | M11: 0.2 | N11: =IF(L11>=M11,"✅ On Track","⚠️ Below Target") -> ✅ On Track
A12: August | B12: =Aug!B12 -> 0 | C12: =Aug!B24 -> 0 | D12: =Aug!B35 -> 0 | E12: =Aug!B46 -> 0 | F12: =C12+D12 -> 0 | G12: =B12-C12-D12-E12 -> 0 | H12: =IF(B12=0,0,E12/B12) -> 0
A13: September | B13: =Sep!B12 -> 0 | C13: =Sep!B24 -> 0 | D13: =Sep!B35 -> 0 | E13: =Sep!B46 -> 0 | F13: =C13+D13 -> 0 | G13: =B13-C13-D13-E13 -> 0 | H13: =IF(B13=0,0,E13/B13) -> 0
A14: October | B14: =Oct!B12 -> 0 | C14: =Oct!B24 -> 0 | D14: =Oct!B35 -> 0 | E14: =Oct!B46 -> 0 | F14: =C14+D14 -> 0 | G14: =B14-C14-D14-E14 -> 0 | H14: =IF(B14=0,0,E14/B14) -> 0
A15: November | B15: =Nov!B12 -> 0 | C15: =Nov!B24 -> 0 | D15: =Nov!B35 -> 0 | E15: =Nov!B46 -> 0 | F15: =C15+D15 -> 0 | G15: =B15-C15-D15-E15 -> 0 | H15: =IF(B15=0,0,E15/B15) -> 0
A16: December | B16: =Dec!B12 -> 0 | C16: =Dec!B24 -> 0 | D16: =Dec!B35 -> 0 | E16: =Dec!B46 -> 0 | F16: =C16+D16 -> 0 | G16: =B16-C16-D16-E16 -> 0 | H16: =IF(B16=0,0,E16/B16) -> 0
A17: TOTAL (YEAR) | B17: =SUM(B5:B16) -> 80000 | C17: =SUM(C5:C16) -> 42000 | D17: =SUM(D5:D16) -> 13000 | E17: =SUM(E5:E16) -> 21000 | F17: =SUM(F5:F16) -> 55000 | G17: =SUM(G5:G16) -> 4000 | H17: =IF(B17=0,0,E17/B17) -> 0.2625
A18: MONTHLY AVERAGE | B18: =AVERAGE(B5:B16) -> 6666.6667 | C18: =AVERAGE(C5:C16) -> 3500 | D18: =AVERAGE(D5:D16) -> 1083.3333 | E18: =AVERAGE(E5:E16) -> 1750 | F18: =AVERAGE(F5:F16) -> 4583.3333 | G18: =AVERAGE(G5:G16) -> 333.33333 | H18: =IF(B18=0,0,E18/B18) -> 0.2625
A20: Fill in each month's tab (Jan–Dec) with your own numbers — this summary and the charts below update automatically.

Sheet Jan
A1: JANUARY 2026 — BUDGET TRACKER
A3: 💰 INCOME | E3: 📊 DASHBOARD | P3: Chart data (auto — leave as is)
A4: Source | B4: Amount (₹) | E4: Total Income | G4: Total Needs | I4: Total Wants | K4: Savings / Invest | M4: Surplus / Deficit | P4: Category | Q4: Amount
A5: Salary | B5: 60000 | E5: =B12 -> 80000 | G5: =B24 -> 42000 | I5: =B35 -> 13000 | K5: =B46 -> 21000 | M5: =B12-B24-B35-B46 -> 4000 | P5: Needs | Q5: =B24 -> 42000
A6: Freelance / Side Income | B6: 15000 | P6: Wants | Q6: =B35 -> 13000
A7: Other Income | B7: 5000 | E7: ✅ BUDGET HEALTH CHECK — 50 / 30 / 20 Rule | P7: Savings/Invest | Q7: =B46 -> 21000
E8: Category | F8: Actual Amount | G8: Actual % | H8: Target % | I8: Status | P8: Leftover | Q8: =MAX(B12-B24-B35-B46,0) -> 4000
E9: Needs (Essentials) | F9: =B24 -> 42000 | G9: =IF($B$12=0,0,F9/$B$12) -> 0.525 | H9: 0.5 | I9: =IF(G9<=H9,"✅ On Track","⚠️ Over Budget") -> ⚠️ Over Budget
E10: Wants (Lifestyle) | F10: =B35 -> 13000 | G10: =IF($B$12=0,0,F10/$B$12) -> 0.1625 | H10: 0.3 | I10: =IF(G10<=H10,"✅ On Track","⚠️ Over Budget") -> ✅ On Track
E11: Savings & Investments | F11: =B46 -> 21000 | G11: =IF($B$12=0,0,F11/$B$12) -> 0.2625 | H11: 0.2 | I11: =IF(G11>=H11,"✅ On Track","⚠️ Below Target") -> ✅ On Track
A12: TOTAL INCOME | B12: =SUM(B5:B11) -> 80000
A14: 🏠 NEEDS — Essential Expenses
A15: Category | B15: Amount (₹)
A16: Rent / Housing | B16: 18000
A17: Groceries & Food | B17: 6000
A18: Utilities (Electricity, Water, Gas) | B18: 2500
A19: EMI / Loan Payments | B19: 8000
A20: Insurance Premiums | B20: 2000
A21: Transportation | B21: 3000
A22: Medical / Health | B22: 1500
A23: Other Needs | B23: 1000
A24: TOTAL NEEDS | B24: =SUM(B16:B23) -> 42000
A26: 🛍️ WANTS — Lifestyle Expenses
A27: Category | B27: Amount (₹)
A28: Shopping | B28: 4000
A29: Dining & Entertainment | B29: 3000
A30: Subscriptions (OTT / Apps) | B30: 1000
A31: Travel & Vacation | B31: 2000
A32: Gifts & Celebrations | B32: 1000
A33: Hobbies & Self-care | B33: 1500
A34: Other Wants | B34: 500
A35: TOTAL WANTS | B35: =SUM(B28:B34) -> 13000
A37: 📈 SAVINGS & INVESTMENTS
A38: Category | B38: Amount (₹)
A39: SIP / Mutual Funds | B39: 10000
A40: Fixed Deposit / RD | B40: 3000
A41: Emergency Fund | B41: 2000
A42: Retirement (PF / NPS) | B42: 3000
A43: Stocks / Equity | B43: 2000
A44: Gold / Other Assets | B44: 1000
...

Sheet Feb
A1: FEBRUARY 2026 — BUDGET TRACKER
A3: 💰 INCOME | E3: 📊 DASHBOARD | P3: Chart data (auto — leave as is)
A4: Source | B4: Amount (₹) | E4: Total Income | G4: Total Needs | I4: Total Wants | K4: Savings / Invest | M4: Surplus / Deficit | P4: Category | Q4: Amount
A5: Salary | E5: =B12 -> 0 | G5: =B24 -> 0 | I5: =B35 -> 0 | K5: =B46 -> 0 | M5: =B12-B24-B35-B46 -> 0 | P5: Needs | Q5: =B24 -> 0
A6: Freelance / Side Income | P6: Wants | Q6: =B35 -> 0
A7: Other Income | E7: ✅ BUDGET HEALTH CHECK — 50 / 30 / 20 Rule | P7: Savings/Invest | Q7: =B46 -> 0
E8: Category | F8: Actual Amount | G8: Actual % | H8: Target % | I8: Status | P8: Leftover | Q8: =MAX(B12-B24-B35-B46,0) -> 0
E9: Needs (Essentials) | F9: =B24 -> 0 | G9: =IF($B$12=0,0,F9/$B$12) -> 0 | H9: 0.5 | I9: =IF(G9<=H9,"✅ On Track","⚠️ Over Budget") -> ✅ On Track
E10: Wants (Lifestyle) | F10: =B35 -> 0 | G10: =IF($B$12=0,0,F10/$B$12) -> 0 | H10: 0.3 | I10: =IF(G10<=H10,"✅ On Track","⚠️ Over Budget") -> ✅ On Track
E11: Savings & Investments | F11: =B46 -> 0 | G11: =IF($B$12=0,0,F11/$B$12) -> 0 | H11: 0.2 | I11: =IF(G11>=H11,"✅ On Track","⚠️ Below Target") -> ⚠️ Below Target
A12: TOTAL INCOME | B12: =SUM(B5:B11) -> 0
A14: 🏠 NEEDS — Essential Expenses
A15: Category | B15: Amount (₹)
A16: Rent / Housing
A17: Groceries & Food
A18: Utilities (Electricity, Water, Gas)
A19: EMI / Loan Payments
A20: Insurance Premiums
A21: Transportation
A22: Medical / Health
A23: Other Needs
A24: TOTAL NEEDS | B24: =SUM(B16:B23) -> 0
A26: 🛍️ WANTS — Lifestyle Expenses
A27: Category | B27: Amount (₹)
A28: Shopping
A29: Dining & Entertainment
A30: Subscriptions (OTT / Apps)
A31: Travel & Vacation
A32: Gifts & Celebrations
A33: Hobbies & Self-care
A34: Other Wants
A35: TOTAL WANTS | B35: =SUM(B28:B34) -> 0
A37: 📈 SAVINGS & INVESTMENTS
A38: Category | B38: Amount (₹)
A39: SIP / Mutual Funds
A40: Fixed Deposit / RD
A41: Emergency Fund
A42: Retirement (PF / NPS)
A43: Stocks / Equity
A44: Gold / Other Assets
...

Sheet Mar
A1: MARCH 2026 — BUDGET TRACKER
A3: 💰 INCOME | E3: 📊 DASHBOARD | P3: Chart data (auto — leave as is)
A4: Source | B4: Amount (₹) | E4: Total Income | G4: Total Needs | I4: Total Wants | K4: Savings / Invest | M4: Surplus / Deficit | P4: Category | Q4: Amount
A5: Salary | E5: =B12 -> 0 | G5: =B24 -> 0 | I5: =B35 -> 0 | K5: =B46 -> 0 | M5: =B12-B24-B35-B46 -> 0 | P5: Needs | Q5: =B24 -> 0
A6: Freelance / Side Income | P6: Wants | Q6: =B35 -> 0
A7: Other Income | E7: ✅ BUDGET HEALTH CHECK — 50 / 30 / 20 Rule | P7: Savings/Invest | Q7: =B46 -> 0
E8: Category | F8: Actual Amount | G8: Actual % | H8: Target % | I8: Status | P8: Leftover | Q8: =MAX(B12-B24-B35-B46,0) -> 0
E9: Needs (Essentials) | F9: =B24 -> 0 | G9: =IF($B$12=0,0,F9/$B$12) -> 0 | H9: 0.5 | I9: =IF(G9<=H9,"✅ On Track","⚠️ Over Budget") -> ✅ On Track
E10: Wants (Lifestyle) | F10: =B35 -> 0 | G10: =IF($B$12=0,0,F10/$B$12) -> 0 | H10: 0.3 | I10: =IF(G10<=H10,"✅ On Track","⚠️ Over Budget") -> ✅ On Track
E11: Savings & Investments | F11: =B46 -> 0 | G11: =IF($B$12=0,0,F11/$B$12) -> 0 | H11: 0.2 | I11: =IF(G11>=H11,"✅ On Track","⚠️ Below Target") -> ⚠️ Below Target
A12: TOTAL INCOME | B12: =SUM(B5:B11) -> 0
A14: 🏠 NEEDS — Essential Expenses
A15: Category | B15: Amount (₹)
A16: Rent / Housing
A17: Groceries & Food
A18: Utilities (Electricity, Water, Gas)
A19: EMI / Loan Payments
A20: Insurance Premiums
A21: Transportation
A22: Medical / Health
A23: Other Needs
A24: TOTAL NEEDS | B24: =SUM(B16:B23) -> 0
A26: 🛍️ WANTS — Lifestyle Expenses
A27: Category | B27: Amount (₹)
A28: Shopping
A29: Dining & Entertainment
A30: Subscriptions (OTT / Apps)
A31: Travel & Vacation
A32: Gifts & Celebrations
A33: Hobbies & Self-care
A34: Other Wants
A35: TOTAL WANTS | B35: =SUM(B28:B34) -> 0
A37: 📈 SAVINGS & INVESTMENTS
A38: Category | B38: Amount (₹)
A39: SIP / Mutual Funds
A40: Fixed Deposit / RD
A41: Emergency Fund
A42: Retirement (PF / NPS)
A43: Stocks / Equity
A44: Gold / Other Assets
...

Sheet Apr
A1: APRIL 2026 — BUDGET TRACKER
A3: 💰 INCOME | E3: 📊 DASHBOARD | P3: Chart data (auto — leave as is)
A4: Source | B4: Amount (₹) | E4: Total Income | G4: Total Needs | I4: Total Wants | K4: Savings / Invest | M4: Surplus / Deficit | P4: Category | Q4: Amount
A5: Salary | E5: =B12 -> 0 | G5: =B24 -> 0 | I5: =B35 -> 0 | K5: =B46 -> 0 | M5: =B12-B24-B35-B46 -> 0 | P5: Needs | Q5: =B24 -> 0
A6: Freelance / Side Income | P6: Wants | Q6: =B35 -> 0
A7: Other Income | E7: ✅ BUDGET HEALTH CHECK — 50 / 30 / 20 Rule | P7: Savings/Invest | Q7: =B46 -> 0
E8: Category | F8: Actual Amount | G8: Actual % | H8: Target % | I8: Status | P8: Leftover | Q8: =MAX(B12-B24-B35-B46,0) -> 0
E9: Needs (Essentials) | F9: =B24 -> 0 | G9: =IF($B$12=0,0,F9/$B$12) -> 0 | H9: 0.5 | I9: =IF(G9<=H9,"✅ On Track","⚠️ Over Budget") -> ✅ On Track
E10: Wants (Lifestyle) | F10: =B35 -> 0 | G10: =IF($B$12=0,0,F10/$B$12) -> 0 | H10: 0.3 | I10: =IF(G10<=H10,"✅ On Track","⚠️ Over Budget") -> ✅ On Track
E11: Savings & Investments | F11: =B46 -> 0 | G11: =IF($B$12=0,0,F11/$B$12) -> 0 | H11: 0.2 | I11: =IF(G11>=H11,"✅ On Track","⚠️ Below Target") -> ⚠️ Below Target
A12: TOTAL INCOME | B12: =SUM(B5:B11) -> 0
A14: 🏠 NEEDS — Essential Expenses
A15: Category | B15: Amount (₹)
A16: Rent / Housing
A17: Groceries & Food
A18: Utilities (Electricity, Water, Gas)
A19: EMI / Loan Payments
A20: Insurance Premiums
A21: Transportation
A22: Medical / Health
A23: Other Needs
A24: TOTAL NEEDS | B24: =SUM(B16:B23) -> 0
A26: 🛍️ WANTS — Lifestyle Expenses
A27: Category | B27: Amount (₹)
A28: Shopping
A29: Dining & Entertainment
A30: Subscriptions (OTT / Apps)
A31: Travel & Vacation
A32: Gifts & Celebrations
A33: Hobbies & Self-care
A34: Other Wants
A35: TOTAL WANTS | B35: =SUM(B28:B34) -> 0
A37: 📈 SAVINGS & INVESTMENTS
A38: Category | B38: Amount (₹)
A39: SIP / Mutual Funds
A40: Fixed Deposit / RD
A41: Emergency Fund
A42: Retirement (PF / NPS)
A43: Stocks / Equity
A44: Gold / Other Assets
...

Sheet May
A1: MAY 2026 — BUDGET TRACKER
A3: 💰 INCOME | E3: 📊 DASHBOARD | P3: Chart data (auto — leave as is)
A4: Source | B4: Amount (₹) | E4: Total Income | G4: Total Needs | I4: Total Wants | K4: Savings / Invest | M4: Surplus / Deficit | P4: Category | Q4: Amount
A5: Salary | E5: =B12 -> 0 | G5: =B24 -> 0 | I5: =B35 -> 0 | K5: =B46 -> 0 | M5: =B12-B24-B35-B46 -> 0 | P5: Needs | Q5: =B24 -> 0
A6: Freelance / Side Income | P6: Wants | Q6: =B35 -> 0
A7: Other Income | E7: ✅ BUDGET HEALTH CHECK — 50 / 30 / 20 Rule | P7: Savings/Invest | Q7: =B46 -> 0
E8: Category | F8: Actual Amount | G8: Actual % | H8: Target % | I8: Status | P8: Leftover | Q8: =MAX(B12-B24-B35-B46,0) -> 0
E9: Needs (Essentials) | F9: =B24 -> 0 | G9: =IF($B$12=0,0,F9/$B$12) -> 0 | H9: 0.5 | I9: =IF(G9<=H9,"✅ On Track","⚠️ Over Budget") -> ✅ On Track
E10: Wants (Lifestyle) | F10: =B35 -> 0 | G10: =IF($B$12=0,0,F10/$B$12) -> 0 | H10: 0.3 | I10: =IF(G10<=H10,"✅ On Track","⚠️ Over Budget") -> ✅ On Track
E11: Savings & Investments | F11: =B46 -> 0 | G11: =IF($B$12=0,0,F11/$B$12) -> 0 | H11: 0.2 | I11: =IF(G11>=H11,"✅ On Track","⚠️ Below Target") -> ⚠️ Below Target
A12: TOTAL INCOME | B12: =SUM(B5:B11) -> 0
A14: 🏠 NEEDS — Essential Expenses
A15: Category | B15: Amount (₹)
A16: Rent / Housing
A17: Groceries & Food
A18: Utilities (Electricity, Water, Gas)
A19: EMI / Loan Payments
A20: Insurance Premiums
A21: Transportation
A22: Medical / Health
A23: Other Needs
A24: TOTAL NEEDS | B24: =SUM(B16:B23) -> 0
A26: 🛍️ WANTS — Lifestyle Expenses
A27: Category | B27: Amount (₹)
A28: Shopping
A29: Dining & Entertainment
A30: Subscriptions (OTT / Apps)
A31: Travel & Vacation
A32: Gifts & Celebrations
A33: Hobbies & Self-care
A34: Other Wants
A35: TOTAL WANTS | B35: =SUM(B28:B34) -> 0
A37: 📈 SAVINGS & INVESTMENTS
A38: Category | B38: Amount (₹)
A39: SIP / Mutual Funds
A40: Fixed Deposit / RD
A41: Emergency Fund
A42: Retirement (PF / NPS)
A43: Stocks / Equity
A44: Gold / Other Assets
...

Sheet Jun
A1: JUNE 2026 — BUDGET TRACKER
A3: 💰 INCOME | E3: 📊 DASHBOARD | P3: Chart data (auto — leave as is)
A4: Source | B4: Amount (₹) | E4: Total Income | G4: Total Needs | I4: Total Wants | K4: Savings / Invest | M4: Surplus / Deficit | P4: Category | Q4: Amount
A5: Salary | E5: =B12 -> 0 | G5: =B24 -> 0 | I5: =B35 -> 0 | K5: =B46 -> 0 | M5: =B12-B24-B35-B46 -> 0 | P5: Needs | Q5: =B24 -> 0
A6: Freelance / Side Income | P6: Wants | Q6: =B35 -> 0
A7: Other Income | E7: ✅ BUDGET HEALTH CHECK — 50 / 30 / 20 Rule | P7: Savings/Invest | Q7: =B46 -> 0
E8: Category | F8: Actual Amount | G8: Actual % | H8: Target % | I8: Status | P8: Leftover | Q8: =MAX(B12-B24-B35-B46,0) -> 0
E9: Needs (Essentials) | F9: =B24 -> 0 | G9: =IF($B$12=0,0,F9/$B$12) -> 0 | H9: 0.5 | I9: =IF(G9<=H9,"✅ On Track","⚠️ Over Budget") -> ✅ On Track
E10: Wants (Lifestyle) | F10: =B35 -> 0 | G10: =IF($B$12=0,0,F10/$B$12) -> 0 | H10: 0.3 | I10: =IF(G10<=H10,"✅ On Track","⚠️ Over Budget") -> ✅ On Track
E11: Savings & Investments | F11: =B46 -> 0 | G11: =IF($B$12=0,0,F11/$B$12) -> 0 | H11: 0.2 | I11: =IF(G11>=H11,"✅ On Track","⚠️ Below Target") -> ⚠️ Below Target
A12: TOTAL INCOME | B12: =SUM(B5:B11) -> 0
A14: 🏠 NEEDS — Essential Expenses
A15: Category | B15: Amount (₹)
A16: Rent / Housing
A17: Groceries & Food
A18: Utilities (Electricity, Water, Gas)
A19: EMI / Loan Payments
A20: Insurance Premiums
A21: Transportation
A22: Medical / Health
A23: Other Needs
A24: TOTAL NEEDS | B24: =SUM(B16:B23) -> 0
A26: 🛍️ WANTS — Lifestyle Expenses
A27: Category | B27: Amount (₹)
A28: Shopping
A29: Dining & Entertainment
A30: Subscriptions (OTT / Apps)
A31: Travel & Vacation
A32: Gifts & Celebrations
A33: Hobbies & Self-care
A34: Other Wants
A35: TOTAL WANTS | B35: =SUM(B28:B34) -> 0
A37: 📈 SAVINGS & INVESTMENTS
A38: Category | B38: Amount (₹)
A39: SIP / Mutual Funds
A40: Fixed Deposit / RD
A41: Emergency Fund
A42: Retirement (PF / NPS)
A43: Stocks / Equity
A44: Gold / Other Assets
...

Sheet Jul
A1: JULY 2026 — BUDGET TRACKER
A3: 💰 INCOME | E3: 📊 DASHBOARD | P3: Chart data (auto — leave as is)
A4: Source | B4: Amount (₹) | E4: Total Income | G4: Total Needs | I4: Total Wants | K4: Savings / Invest | M4: Surplus / Deficit | P4: Category | Q4: Amount
A5: Salary | E5: =B12 -> 0 | G5: =B24 -> 0 | I5: =B35 -> 0 | K5: =B46 -> 0 | M5: =B12-B24-B35-B46 -> 0 | P5: Needs | Q5: =B24 -> 0
A6: Freelance / Side Income | P6: Wants | Q6: =B35 -> 0
A7: Other Income | E7: ✅ BUDGET HEALTH CHECK — 50 / 30 / 20 Rule | P7: Savings/Invest | Q7: =B46 -> 0
E8: Category | F8: Actual Amount | G8: Actual % | H8: Target % | I8: Status | P8: Leftover | Q8: =MAX(B12-B24-B35-B46,0) -> 0
E9: Needs (Essentials) | F9: =B24 -> 0 | G9: =IF($B$12=0,0,F9/$B$12) -> 0 | H9: 0.5 | I9: =IF(G9<=H9,"✅ On Track","⚠️ Over Budget") -> ✅ On Track
E10: Wants (Lifestyle) | F10: =B35 -> 0 | G10: =IF($B$12=0,0,F10/$B$12) -> 0 | H10: 0.3 | I10: =IF(G10<=H10,"✅ On Track","⚠️ Over Budget") -> ✅ On Track
E11: Savings & Investments | F11: =B46 -> 0 | G11: =IF($B$12=0,0,F11/$B$12) -> 0 | H11: 0.2 | I11: =IF(G11>=H11,"✅ On Track","⚠️ Below Target") -> ⚠️ Below Target
A12: TOTAL INCOME | B12: =SUM(B5:B11) -> 0
A14: 🏠 NEEDS — Essential Expenses
A15: Category | B15: Amount (₹)
A16: Rent / Housing
A17: Groceries & Food
A18: Utilities (Electricity, Water, Gas)
A19: EMI / Loan Payments
A20: Insurance Premiums
A21: Transportation
A22: Medical / Health
A23: Other Needs
A24: TOTAL NEEDS | B24: =SUM(B16:B23) -> 0
A26: 🛍️ WANTS — Lifestyle Expenses
A27: Category | B27: Amount (₹)
A28: Shopping
A29: Dining & Entertainment
A30: Subscriptions (OTT / Apps)
A31: Travel & Vacation
A32: Gifts & Celebrations
A33: Hobbies & Self-care
A34: Other Wants
A35: TOTAL WANTS | B35: =SUM(B28:B34) -> 0
A37: 📈 SAVINGS & INVESTMENTS
A38: Category | B38: Amount (₹)
A39: SIP / Mutual Funds
A40: Fixed Deposit / RD
A41: Emergency Fund
A42: Retirement (PF / NPS)
A43: Stocks / Equity
A44: Gold / Other Assets
...

Sheet Aug
A1: AUGUST 2026 — BUDGET TRACKER
A3: 💰 INCOME | E3: 📊 DASHBOARD | P3: Chart data (auto — leave as is)
A4: Source | B4: Amount (₹) | E4: Total Income | G4: Total Needs | I4: Total Wants | K4: Savings / Invest | M4: Surplus / Deficit | P4: Category | Q4: Amount
A5: Salary | E5: =B12 -> 0 | G5: =B24 -> 0 | I5: =B35 -> 0 | K5: =B46 -> 0 | M5: =B12-B24-B35-B46 -> 0 | P5: Needs | Q5: =B24 -> 0
A6: Freelance / Side Income | P6: Wants | Q6: =B35 -> 0
A7: Other Income | E7: ✅ BUDGET HEALTH CHECK — 50 / 30 / 20 Rule | P7: Savings/Invest | Q7: =B46 -> 0
E8: Category | F8: Actual Amount | G8: Actual % | H8: Target % | I8: Status | P8: Leftover | Q8: =MAX(B12-B24-B35-B46,0) -> 0
E9: Needs (Essentials) | F9: =B24 -> 0 | G9: =IF($B$12=0,0,F9/$B$12) -> 0 | H9: 0.5 | I9: =IF(G9<=H9,"✅ On Track","⚠️ Over Budget") -> ✅ On Track
E10: Wants (Lifestyle) | F10: =B35 -> 0 | G10: =IF($B$12=0,0,F10/$B$12) -> 0 | H10: 0.3 | I10: =IF(G10<=H10,"✅ On Track","⚠️ Over Budget") -> ✅ On Track
E11: Savings & Investments | F11: =B46 -> 0 | G11: =IF($B$12=0,0,F11/$B$12) -> 0 | H11: 0.2 | I11: =IF(G11>=H11,"✅ On Track","⚠️ Below Target") -> ⚠️ Below Target
A12: TOTAL INCOME | B12: =SUM(B5:B11) -> 0
A14: 🏠 NEEDS — Essential Expenses
A15: Category | B15: Amount (₹)
A16: Rent / Housing
A17: Groceries & Food
A18: Utilities (Electricity, Water, Gas)
A19: EMI / Loan Payments
A20: Insurance Premiums
A21: Transportation
A22: Medical / Health
A23: Other Needs
A24: TOTAL NEEDS | B24: =SUM(B16:B23) -> 0
A26: 🛍️ WANTS — Lifestyle Expenses
A27: Category | B27: Amount (₹)
A28: Shopping
A29: Dining & Entertainment
A30: Subscriptions (OTT / Apps)
A31: Travel & Vacation
A32: Gifts & Celebrations
A33: Hobbies & Self-care
A34: Other Wants
A35: TOTAL WANTS | B35: =SUM(B28:B34) -> 0
A37: 📈 SAVINGS & INVESTMENTS
A38: Category | B38: Amount (₹)
A39: SIP / Mutual Funds
A40: Fixed Deposit / RD
A41: Emergency Fund
A42: Retirement (PF / NPS)
A43: Stocks / Equity
A44: Gold / Other Assets
...

Sheet Sep
A1: SEPTEMBER 2026 — BUDGET TRACKER
A3: 💰 INCOME | E3: 📊 DASHBOARD | P3: Chart data (auto — leave as is)
A4: Source | B4: Amount (₹) | E4: Total Income | G4: Total Needs | I4: Total Wants | K4: Savings / Invest | M4: Surplus / Deficit | P4: Category | Q4: Amount
A5: Salary | E5: =B12 -> 0 | G5: =B24 -> 0 | I5: =B35 -> 0 | K5: =B46 -> 0 | M5: =B12-B24-B35-B46 -> 0 | P5: Needs | Q5: =B24 -> 0
A6: Freelance / Side Income | P6: Wants | Q6: =B35 -> 0
A7: Other Income | E7: ✅ BUDGET HEALTH CHECK — 50 / 30 / 20 Rule | P7: Savings/Invest | Q7: =B46 -> 0
E8: Category | F8: Actual Amount | G8: Actual % | H8: Target % | I8: Status | P8: Leftover | Q8: =MAX(B12-B24-B35-B46,0) -> 0
E9: Needs (Essentials) | F9: =B24 -> 0 | G9: =IF($B$12=0,0,F9/$B$12) -> 0 | H9: 0.5 | I9: =IF(G9<=H9,"✅ On Track","⚠️ Over Budget") -> ✅ On Track
E10: Wants (Lifestyle) | F10: =B35 -> 0 | G10: =IF($B$12=0,0,F10/$B$12) -> 0 | H10: 0.3 | I10: =IF(G10<=H10,"✅ On Track","⚠️ Over Budget") -> ✅ On Track
E11: Savings & Investments | F11: =B46 -> 0 | G11: =IF($B$12=0,0,F11/$B$12) -> 0 | H11: 0.2 | I11: =IF(G11>=H11,"✅ On Track","⚠️ Below Target") -> ⚠️ Below Target
A12: TOTAL INCOME | B12: =SUM(B5:B11) -> 0
A14: 🏠 NEEDS — Essential Expenses
A15: Category | B15: Amount (₹)
A16: Rent / Housing
A17: Groceries & Food
A18: Utilities (Electricity, Water, Gas)
A19: EMI / Loan Payments
A20: Insurance Premiums
A21: Transportation
A22: Medical / Health
A23: Other Needs
A24: TOTAL NEEDS | B24: =SUM(B16:B23) -> 0
A26: 🛍️ WANTS — Lifestyle Expenses
A27: Category | B27: Amount (₹)
A28: Shopping
A29: Dining & Entertainment
A30: Subscriptions (OTT / Apps)
A31: Travel & Vacation
A32: Gifts & Celebrations
A33: Hobbies & Self-care
A34: Other Wants
A35: TOTAL WANTS | B35: =SUM(B28:B34) -> 0
A37: 📈 SAVINGS & INVESTMENTS
A38: Category | B38: Amount (₹)
A39: SIP / Mutual Funds
A40: Fixed Deposit / RD
A41: Emergency Fund
A42: Retirement (PF / NPS)
A43: Stocks / Equity
A44: Gold / Other Assets
...

Sheet Oct
A1: OCTOBER 2026 — BUDGET TRACKER
A3: 💰 INCOME | E3: 📊 DASHBOARD | P3: Chart data (auto — leave as is)
A4: Source | B4: Amount (₹) | E4: Total Income | G4: Total Needs | I4: Total Wants | K4: Savings / Invest | M4: Surplus / Deficit | P4: Category | Q4: Amount
A5: Salary | E5: =B12 -> 0 | G5: =B24 -> 0 | I5: =B35 -> 0 | K5: =B46 -> 0 | M5: =B12-B24-B35-B46 -> 0 | P5: Needs | Q5: =B24 -> 0
A6: Freelance / Side Income | P6: Wants | Q6: =B35 -> 0
A7: Other Income | E7: ✅ BUDGET HEALTH CHECK — 50 / 30 / 20 Rule | P7: Savings/Invest | Q7: =B46 -> 0
E8: Category | F8: Actual Amount | G8: Actual % | H8: Target % | I8: Status | P8: Leftover | Q8: =MAX(B12-B24-B35-B46,0) -> 0
E9: Needs (Essentials) | F9: =B24 -> 0 | G9: =IF($B$12=0,0,F9/$B$12) -> 0 | H9: 0.5 | I9: =IF(G9<=H9,"✅ On Track","⚠️ Over Budget") -> ✅ On Track
E10: Wants (Lifestyle) | F10: =B35 -> 0 | G10: =IF($B$12=0,0,F10/$B$12) -> 0 | H10: 0.3 | I10: =IF(G10<=H10,"✅ On Track","⚠️ Over Budget") -> ✅ On Track
E11: Savings & Investments | F11: =B46 -> 0 | G11: =IF($B$12=0,0,F11/$B$12) -> 0 | H11: 0.2 | I11: =IF(G11>=H11,"✅ On Track","⚠️ Below Target") -> ⚠️ Below Target
A12: TOTAL INCOME | B12: =SUM(B5:B11) -> 0
A14: 🏠 NEEDS — Essential Expenses
A15: Category | B15: Amount (₹)
A16: Rent / Housing
A17: Groceries & Food
A18: Utilities (Electricity, Water, Gas)
A19: EMI / Loan Payments
A20: Insurance Premiums
A21: Transportation
A22: Medical / Health
A23: Other Needs
A24: TOTAL NEEDS | B24: =SUM(B16:B23) -> 0
A26: 🛍️ WANTS — Lifestyle Expenses
A27: Category | B27: Amount (₹)
A28: Shopping
A29: Dining & Entertainment
A30: Subscriptions (OTT / Apps)
A31: Travel & Vacation
A32: Gifts & Celebrations
A33: Hobbies & Self-care
A34: Other Wants
A35: TOTAL WANTS | B35: =SUM(B28:B34) -> 0
A37: 📈 SAVINGS & INVESTMENTS
A38: Category | B38: Amount (₹)
A39: SIP / Mutual Funds
A40: Fixed Deposit / RD
A41: Emergency Fund
A42: Retirement (PF / NPS)
A43: Stocks / Equity
A44: Gold / Other Assets
...

Sheet Nov
A1: NOVEMBER 2026 — BUDGET TRACKER
A3: 💰 INCOME | E3: 📊 DASHBOARD | P3: Chart data (auto — leave as is)
A4: Source | B4: Amount (₹) | E4: Total Income | G4: Total Needs | I4: Total Wants | K4: Savings / Invest | M4: Surplus / Deficit | P4: Category | Q4: Amount
A5: Salary | E5: =B12 -> 0 | G5: =B24 -> 0 | I5: =B35 -> 0 | K5: =B46 -> 0 | M5: =B12-B24-B35-B46 -> 0 | P5: Needs | Q5: =B24 -> 0
A6: Freelance / Side Income | P6: Wants | Q6: =B35 -> 0
A7: Other Income | E7: ✅ BUDGET HEALTH CHECK — 50 / 30 / 20 Rule | P7: Savings/Invest | Q7: =B46 -> 0
E8: Category | F8: Actual Amount | G8: Actual % | H8: Target % | I8: Status | P8: Leftover | Q8: =MAX(B12-B24-B35-B46,0) -> 0
E9: Needs (Essentials) | F9: =B24 -> 0 | G9: =IF($B$12=0,0,F9/$B$12) -> 0 | H9: 0.5 | I9: =IF(G9<=H9,"✅ On Track","⚠️ Over Budget") -> ✅ On Track
E10: Wants (Lifestyle) | F10: =B35 -> 0 | G10: =IF($B$12=0,0,F10/$B$12) -> 0 | H10: 0.3 | I10: =IF(G10<=H10,"✅ On Track","⚠️ Over Budget") -> ✅ On Track
E11: Savings & Investments | F11: =B46 -> 0 | G11: =IF($B$12=0,0,F11/$B$12) -> 0 | H11: 0.2 | I11: =IF(G11>=H11,"✅ On Track","⚠️ Below Target") -> ⚠️ Below Target
A12: TOTAL INCOME | B12: =SUM(B5:B11) -> 0
A14: 🏠 NEEDS — Essential Expenses
A15: Category | B15: Amount (₹)
A16: Rent / Housing
A17: Groceries & Food
A18: Utilities (Electricity, Water, Gas)
A19: EMI / Loan Payments
A20: Insurance Premiums
A21: Transportation
A22: Medical / Health
A23: Other Needs
A24: TOTAL NEEDS | B24: =SUM(B16:B23) -> 0
A26: 🛍️ WANTS — Lifestyle Expenses
A27: Category | B27: Amount (₹)
A28: Shopping
A29: Dining & Entertainment
A30: Subscriptions (OTT / Apps)
A31: Travel & Vacation
A32: Gifts & Celebrations
A33: Hobbies & Self-care
A34: Other Wants
A35: TOTAL WANTS | B35: =SUM(B28:B34) -> 0
A37: 📈 SAVINGS & INVESTMENTS
A38: Category | B38: Amount (₹)
A39: SIP / Mutual Funds
A40: Fixed Deposit / RD
A41: Emergency Fund
A42: Retirement (PF / NPS)
A43: Stocks / Equity
A44: Gold / Other Assets
...

Sheet Dec
A1: DECEMBER 2026 — BUDGET TRACKER
A3: 💰 INCOME | E3: 📊 DASHBOARD | P3: Chart data (auto — leave as is)
A4: Source | B4: Amount (₹) | E4: Total Income | G4: Total Needs | I4: Total Wants | K4: Savings / Invest | M4: Surplus / Deficit | P4: Category | Q4: Amount
A5: Salary | E5: =B12 -> 0 | G5: =B24 -> 0 | I5: =B35 -> 0 | K5: =B46 -> 0 | M5: =B12-B24-B35-B46 -> 0 | P5: Needs | Q5: =B24 -> 0
A6: Freelance / Side Income | P6: Wants | Q6: =B35 -> 0
A7: Other Income | E7: ✅ BUDGET HEALTH CHECK — 50 / 30 / 20 Rule | P7: Savings/Invest | Q7: =B46 -> 0
E8: Category | F8: Actual Amount | G8: Actual % | H8: Target % | I8: Status | P8: Leftover | Q8: =MAX(B12-B24-B35-B46,0) -> 0
E9: Needs (Essentials) | F9: =B24 -> 0 | G9: =IF($B$12=0,0,F9/$B$12) -> 0 | H9: 0.5 | I9: =IF(G9<=H9,"✅ On Track","⚠️ Over Budget") -> ✅ On Track
E10: Wants (Lifestyle) | F10: =B35 -> 0 | G10: =IF($B$12=0,0,F10/$B$12) -> 0 | H10: 0.3 | I10: =IF(G10<=H10,"✅ On Track","⚠️ Over Budget") -> ✅ On Track
E11: Savings & Investments | F11: =B46 -> 0 | G11: =IF($B$12=0,0,F11/$B$12) -> 0 | H11: 0.2 | I11: =IF(G11>=H11,"✅ On Track","⚠️ Below Target") -> ⚠️ Below Target
A12: TOTAL INCOME | B12: =SUM(B5:B11) -> 0
A14: 🏠 NEEDS — Essential Expenses
A15: Category | B15: Amount (₹)
A16: Rent / Housing
A17: Groceries & Food
A18: Utilities (Electricity, Water, Gas)
A19: EMI / Loan Payments
A20: Insurance Premiums
A21: Transportation
A22: Medical / Health
A23: Other Needs
A24: TOTAL NEEDS | B24: =SUM(B16:B23) -> 0
A26: 🛍️ WANTS — Lifestyle Expenses
A27: Category | B27: Amount (₹)
A28: Shopping
A29: Dining & Entertainment
A30: Subscriptions (OTT / Apps)
A31: Travel & Vacation
A32: Gifts & Celebrations
A33: Hobbies & Self-care
A34: Other Wants
A35: TOTAL WANTS | B35: =SUM(B28:B34) -> 0
A37: 📈 SAVINGS & INVESTMENTS
A38: Category | B38: Amount (₹)
A39: SIP / Mutual Funds
A40: Fixed Deposit / RD
A41: Emergency Fund
A42: Retirement (PF / NPS)
A43: Stocks / Equity
A44: Gold / Other Assets
...
